Workbook

Sheet Sommaire
B2: Cahier de recettes
B3: Mini-ERP — SaaS multi-tenant (commerce de détail & gros)
B4: Plan de tests d'acceptation (recette fonctionnelle / UAT)
B6: Projet | C6: Mini-ERP
B7: Version du document | C7: v1.0
B8: Branche / état testé | C8: main (rejeu post-correctifs 2026-06-24, commit a355ca7)
B9: Date de génération | C9: 2026-06-24
B10: Environnement | C10: admin http://localhost:4200 · POS http://localhost:4201 · API http://localhost:8080
B11: Comptes de test | C11: tenant isolé « recette2 » — admin@recette2.local / Recette1234!
B12: Rédacteur | C12: Recette automatisée (10 agents par domaine, API réelle + Playwright)
B13: Validé par | C13: À compléter
B15: Objet
B16: Ce cahier de recettes décrit les cas de test à exécuter pour valider le bon fonctionnement du Mini-ERP avant mise en production. Chaque cas précise les pré-requis, le jeu de données, les étapes et le résultat attendu ; le testeur renseigne le Statut, son nom, la date et d'éventuelles observations.
B19: Légende des statuts
B20: À tester | C20: Cas non encore exécuté (valeur par défaut)
B21: OK | C21: Conforme au résultat attendu
B22: KO | C22: Non conforme — anomalie à consigner
B23: Bloqué | C23: Exécution impossible (dépendance, données)
B24: N/A | C24: Non applicable dans ce périmètre
B26: Périmètre & avancement
B27: Domaine fonctionnel | C27: Nb cas | D27: À tester | E27: OK | F27: KO | G27: Bloqué
B28: Authentification, Sécurité, Utilisateurs, Tenants, Paramètres, Notifications, Audit | C28: 49 | D28: =COUNTIF('01 - Auth & Admin'!$J$3:$J$51,"À tester") | E28: =COUNTIF('01 - Auth & Admin'!$J$3:$J$51,"OK") | F28: =COUNTIF('01 - Auth & Admin'!$J$3:$J$51,"KO") | G28: =COUNTIF('01 - Auth & Admin'!$J$3:$J$51,"Bloqué")
B29: Partenaires (clients/fournisseurs unifiés), crédits, relevé de compte | C29: 27 | D29: =COUNTIF('02 - Partenaires'!$J$3:$J$29,"À tester") | E29: =COUNTIF('02 - Partenaires'!$J$3:$J$29,"OK") | F29: =COUNTIF('02 - Partenaires'!$J$3:$J$29,"KO") | G29: =COUNTIF('02 - Partenaires'!$J$3:$J$29,"Bloqué")
B30: Produits, Variantes, Attributs, Unités de mesure, Tarification | C30: 55 | D30: =COUNTIF('03 - Catalogue & Tarifs'!$J$3:$J$57,"À tester") | E30: =COUNTIF('03 - Catalogue & Tarifs'!$J$3:$J$57,"OK") | F30: =COUNTIF('03 - Catalogue & Tarifs'!$J$3:$J$57,"KO") | G30: =COUNTIF('03 - Catalogue & Tarifs'!$J$3:$J$57,"Bloqué")
B31: Entrepôts, Stock & mouvements, Transferts, Inventaire physique | C31: 37 | D31: =COUNTIF('04 - Stock & Inventaire'!$J$3:$J$39,"À tester") | E31: =COUNTIF('04 - Stock & Inventaire'!$J$3:$J$39,"OK") | F31: =COUNTIF('04 - Stock & Inventaire'!$J$3:$J$39,"KO") | G31: =COUNTIF('04 - Stock & Inventaire'!$J$3:$J$39,"Bloqué")
B32: Lots, FEFO, alertes d'expiration, blocage, destruction, étiquettes | C32: 28 | D32: =COUNTIF('05 - Lots & Expiration'!$J$3:$J$30,"À tester") | E32: =COUNTIF('05 - Lots & Expiration'!$J$3:$J$30,"OK") | F32: =COUNTIF('05 - Lots & Expiration'!$J$3:$J$30,"KO") | G32: =COUNTIF('05 - Lots & Expiration'!$J$3:$J$30,"Bloqué")
B33: Devis, Factures, Avoirs client, Bons de livraison | C33: 49 | D33: =COUNTIF('06 - Ventes & Livraisons'!$J$3:$J$51,"À tester") | E33: =COUNTIF('06 - Ventes & Livraisons'!$J$3:$J$51,"OK") | F33: =COUNTIF('06 - Ventes & Livraisons'!$J$3:$J$51,"KO") | G33: =COUNTIF('06 - Ventes & Livraisons'!$J$3:$J$51,"Bloqué")
B34: Commandes, Factures fournisseur, Réceptions, Avoirs/Retours | C34: 47 | D34: =COUNTIF('07 - Achats'!$J$3:$J$49,"À tester") | E34: =COUNTIF('07 - Achats'!$J$3:$J$49,"OK") | F34: =COUNTIF('07 - Achats'!$J$3:$J$49,"KO") | G34: =COUNTIF('07 - Achats'!$J$3:$J$49,"Bloqué")
B35: Paiements & Allocations, Dépenses, Trésorerie | C35: 47 | D35: =COUNTIF('08 - Paiements & Trésor.'!$J$3:$J$49,"À tester") | E35: =COUNTIF('08 - Paiements & Trésor.'!$J$3:$J$49,"OK") | F35: =COUNTIF('08 - Paiements & Trésor.'!$J$3:$J$49,"KO") | G35: =COUNTIF('08 - Paiements & Trésor.'!$J$3:$J$49,"Bloqué")
B36: Point de vente, Sessions de caisse, hors-ligne/sync, validation | C36: 34 | D36: =COUNTIF('09 - POS & Caisse'!$J$3:$J$36,"À tester") | E36: =COUNTIF('09 - POS & Caisse'!$J$3:$J$36,"OK") | F36: =COUNTIF('09 - POS & Caisse'!$J$3:$J$36,"KO") | G36: =COUNTIF('09 - POS & Caisse'!$J$3:$J$36,"Bloqué")
B37: Rapports & tableaux de bord, Documents PDF, Internationalisation | C37: 46 | D37: =COUNTIF('10 - Reporting & i18n'!$J$3:$J$48,"À tester") | E37: =COUNTIF('10 - Reporting & i18n'!$J$3:$J$48,"OK") | F37: =COUNTIF('10 - Reporting & i18n'!$J$3:$J$48,"KO") | G37: =COUNTIF('10 - Reporting & i18n'!$J$3:$J$48,"Bloqué")
B38: TOTAL | C38: =SUM(C28:C37) | D38: =SUM(D28:D37) | E38: =SUM(E28:E37) | F38: =SUM(F28:F37) | G38: =SUM(G28:G37)

Sheet Bugs & Anomalies
A1: Bugs & anomalies — rejeu sur main du 2026-06-24 (tenant recette2)
A2: 0 KO · 0 régression(s) · 2 Bloqué. Rappel : 19 KO au 2026-06-24, corrigés P0→P2 et mergés (a355ca7) — ce rejeu confirme l'état sur main.
A4: ID | B4: Domaine | C4: Statut | D4: Prior (24/06) | E4: Régression | F4: Observation / preuve
A5: — Cas restés Bloqué —
A6: LOT-15 | B6: D05 | C6: Bloqué | D6: Bloqué | F6: [Bloqué — inchangé] La consommation FEFO AUTOMATIQUE est désormais câblée (cf. LOT-13/14), mais la SÉLECTION MANUELLE d'un lot précis (court-circuit de l'ordre FEFO) reste non exposée via l'API/UI : c'est une fonctionnalité distincte non implémentée. consumeAllocations(lotId explicite) existe au niveau SPI (testé) mais aucun écran/endpoint de vente ne permet de choisir le lot.
A7: BRC-17 | B7: D07 | C7: Bloqué | D7: Bloqué | F7: Chemin error.reception.already_posted non atteignable via l'API publique : POST /record fixe TOUJOURS le bon à RECEIVED (statut terminal). Tentative de déblocage: record partiel 2/4 sur un BRC IN_PROGRESS -> statut=RECEIVED ; cancel ensuite -> 422 code=error.reception.already_received (already_received, jamais already_posted). La garde existe (GoodsReceiptService) mais n'est pas déclenchable par le flux normal record->cancel.

Sheet 01 - Auth & Admin
A1: 01 - Auth & Admin — Authentification, Sécurité, Utilisateurs, Tenants, Paramètres, Notifications, Audit
A2: ID | B2: Module | C2: Fonctionnalité | D2: Cas de test | E2: Pré-requis | F2: Jeu de données | G2: Étapes | H2: Résultat attendu | I2: Priorité | J2: Statut | K2: Testeur | L2: Date | M2: Observations / Anomalie
A3: AUTH-01 | B3: Authentification & Sécurité | C3: Connexion | D3: Connexion réussie d'un utilisateur valide | E3: Tenant 'demo' actif (statut TRIAL ou ACTIVE). Utilisateur admin@demo.local actif avec mot de passe connu, non verrouillé. | F3: Code organisation : demo / Email : admin@demo.local / Mot de passe : Admin1234! | G3: 1. Ouvrir la page /auth/login. 2. Saisir le code organisation 'demo', l'email 'admin@demo.local' et le mot de passe 'Admin1234!'. 3. Cliquer sur « Se connecter ». | H3: Réponse HTTP 200 de POST /api/v1/auth/login renvoyant accessToken, refreshToken, accessTokenExpiresInSeconds et le profil utilisateur. Redirection vers le tableau de bord. L'événement d'audit LOGIN_SUCCESS est enregistré et le compteur d'échecs est remis à 0. | I3: Haute | J3: OK | K3: Recette auto (main) — agents | L3: 2026-06-24 | M3: [API+Visuel] POST /auth/login (recette2/admin@recette2.local/Recette1234!) -> 200 avec accessToken, refreshToken, accessTokenExpiresInSeconds=3600, roles=[TENANT_ADMIN]. Page login : formulaire rempli avec creds valides (capture). [captures: AUTH-01_login_filled.png]
A4: AUTH-02 | B4: Authentification & Sécurité | C4: Connexion | D4: Connexion refusée avec mot de passe erroné | E4: Tenant 'demo' actif. Utilisateur admin@demo.local existant et non verrouillé (moins de 5 échecs). | F4: Code organisation : demo / Email : admin@demo.local / Mot de passe : MauvaisMotDePasse | G4: 1. Ouvrir /auth/login. 2. Saisir 'demo', 'admin@demo.local' et un mot de passe incorrect. 3. Cliquer sur « Se connecter ». | H4: Réponse HTTP 401 avec code auth.bad_credentials et message « Identifiants invalides ». Le compteur failedLoginAttempts de l'utilisateur est incrémenté de 1. Aucun token n'est délivré. | I4: Haute | J4: OK | K4: Recette auto (main) — agents | L4: 2026-06-24 | M4: [API] Login avec mauvais mot de passe -> 401 code auth.bad_credentials, message « Identifiants invalides », aucun token. Testé sur un user jetable (r2-d01-lock) pour ne JAMAIS verrouiller l'admin partagé. [captures: AUTH-02_login_wrong_pw_state.png]
A5: AUTH-03 | B5: Authentification & Sécurité | C5: Connexion | D5: Connexion refusée avec email inconnu (pas de fuite d'information) | E5: Tenant 'demo' actif. Aucun utilisateur 'inconnu@demo.local' dans ce tenant. | F5: Code organisation : demo / Email : inconnu@demo.local / Mot de passe : Quelconque1! | G5: 1. Ouvrir /auth/login. 2. Saisir 'demo', un email inexistant et un mot de passe quelconque. 3. Cliquer sur « Se connecter ». | H5: Réponse HTTP 401 avec code auth.bad_credentials et message « Identifiants invalides » (même message que pour un mot de passe erroné, sans révéler si l'email existe). | I5: Moyenne | J5: OK | K5: Recette auto (main) — agents | L5: 2026-06-24 | M5: [API] Login avec email inconnu -> MÊME 401 auth.bad_credentials / « Identifiants invalides » qu'un mot de passe erroné : aucune fuite d'existence.
A6: AUTH-04 | B6: Authentification & Sécurité | C6: Connexion | D6: Verrouillage du compte après 5 échecs consécutifs | E6: Tenant 'demo' actif. Utilisateur cible non verrouillé, compteur d'échecs à 0. | F6: Code organisation : demo / Email : caissier@demo.local / Mot de passe erroné répété 5 fois | G6: 1. Saisir un mauvais mot de passe et soumettre — répéter cette opération 5 fois. 2. Au 5e échec, observer la bascule. 3. Tenter une 6e connexion, même avec le bon mot de passe. | H6: Du 1er au 5e échec : HTTP 401 auth.bad_credentials. Au 5e échec atteint (MAX_FAILED_ATTEMPTS = 5), lockedUntil est positionné à maintenant + 15 minutes et le compteur est remis à 0. La 6e tentative renvoie HTTP 403 code auth.account_locked, message « Compte verrouillé. Réessayez plus tard. » même si le mot de passe est correct. | I6: Haute | J6: OK | K6: Recette auto (main) — agents | L6: 2026-06-24 | M6: [API] CORRIGÉ (prior=KO 2026-06-24). Sur un user jetable : 5 échecs renvoient [401,401,401,401,403] puis 6e tentative avec le BON mot de passe -> 403 code auth.account_locked « Compte verrouillé après 5 tentatives. Réessayez dans 15 minutes. ». Le verrouillage est désormais bien persisté (plus de rollback transactionnel). L'admin partagé n'a jamais été touché.
A7: AUTH-05 | B7: Authentification & Sécurité | C7: Connexion | D7: Code organisation inexistant à la connexion | E7: Aucun tenant dont le code est 'tenant-fantome'. | F7: Code organisation : tenant-fantome / Email : admin@demo.local / Mot de passe : Admin1234! | G7: 1. Ouvrir /auth/login. 2. Saisir un code organisation inexistant et des identifiants quelconques. 3. Cliquer sur « Se connecter ». | H7: Réponse HTTP 404 avec code tenant.not_found (le tenant est résolu avant la vérification des identifiants). Aucun token n'est délivré. | I7: Moyenne | J7: OK | K7: Recette auto (main) — agents | L7: 2026-06-24 | M7: [API] Login sur tenantCode inexistant 'tenant-fantome-*' -> 404 code tenant.not_found (tenant résolu avant les identifiants), aucun token.
A8: AUTH-06 | B8: Authentification & Sécurité | C8: Connexion | D8: Code organisation manquant à la connexion | E8: Page de connexion accessible. | F8: Code organisation : (vide) / Email : admin@demo.local / Mot de passe : Admin1234! | G8: 1. Laisser le champ code organisation vide. 2. Saisir email et mot de passe. 3. Tenter de soumettre (forcer l'appel API si le bouton est bloqué par la validation front). | H8: Le formulaire front bloque la soumission (champ requis). Côté API, un appel sans tenantCode renvoie HTTP 404 code tenant.not_found (code « <missing> »). | I8: Basse | J8: OK | K8: Recette auto (main) — agents | L8: 2026-06-24 | M8: [API+Visuel] Login sans tenantCode -> HTTP 422 code tenant.not_found (code=<missing>), aucun token. Front : champ « Code organisation » requis, bouton bloqué tant que le formulaire est incomplet (capture). Écart mineur de code HTTP (422 vs 404 attendu) identique au 2026-06-24 ; le code métier tenant.not_found est bien présent. [captures: AUTH-06_login_empty.png]
A9: AUTH-07 | B9: Authentification & Sécurité | C9: Connexion - cycle de vie tenant | D9: Connexion bloquée sur un tenant SUSPENDED (utilisateur non super-admin) | E9: Tenant 'suspendu-co' au statut SUSPENDED avec un utilisateur standard actif et identifiants valides. | F9: Code organisation : suspendu-co / Email : admin@suspendu-co / Mot de passe valide | G9: 1. Ouvrir /auth/login. 2. Saisir le code du tenant suspendu et des identifiants corrects. 3. Cliquer sur « Se connecter ». | H9: Réponse HTTP 403 code auth.tenant_suspended. Aucun token délivré. (Les statuts PENDING → auth.tenant_pending et ARCHIVED → auth.tenant_archived sont bloqués de la même manière ; TRIAL, ACTIVE et PAST_DUE restent autorisés.) | I9: Haute | J9: OK | K9: Recette auto (main) — agents | L9: 2026-06-24 | M9: [API+Visuel] Tenant jetable r2d01-life-* provisionné puis mis en SUSPENDED (visible « Suspendu » dans la console Organisations). Login de son admin (utilisateur standard) -> 403 code auth.tenant_suspended, aucun token. [captures: TEN-04_organizations_console.png]
A10: AUTH-08 | B10: Authentification & Sécurité | C10: Connexion - cycle de vie tenant | D10: Le super-admin peut se connecter à un tenant non opérationnel | E10: Tenant 'suspendu-co' au statut SUSPENDED. Utilisateur super-admin (flag is_super_admin) rattaché. | F10: Code organisation : suspendu-co / Email : super@plateforme / Mot de passe valide | G10: 1. Ouvrir /auth/login. 2. Saisir le code du tenant suspendu et les identifiants du super-admin. 3. Cliquer sur « Se connecter ». | H10: Réponse HTTP 200 : le super-admin contourne le contrôle ensureTenantLoggable et obtient ses tokens, afin de pouvoir réactiver le tenant. Le rôle SUPER_ADMIN figure dans le profil renvoyé. | I10: Moyenne | J10: OK | K10: Recette auto (main) — agents | L10: 2026-06-24 | M10: [VÉRIF] Débloqué (promotion super-admin via DB) : sur un tenant SUSPENDED, l'admin standard → 403 auth.tenant_suspended, mais le même user promu super_admin → 200 (roles [SUPER_ADMIN,TENANT_ADMIN]). Le contournement super-admin est confirmé.
A11: AUTH-09 | B11: Authentification & Sécurité | C11: Rafraîchissement de token | D11: Rotation du refresh token | E11: Une session ouverte ayant fourni un refreshToken valide et non révoqué. | F11: refreshToken : <valeur obtenue à la connexion> | G11: 1. Appeler POST /api/v1/auth/refresh avec le refreshToken courant. 2. Récupérer la réponse. 3. Réessayer POST /api/v1/auth/refresh avec l'ANCIEN refreshToken. | H11: Le premier appel renvoie HTTP 200 avec un nouvel accessToken ET un nouveau refreshToken (rotation : l'ancien est marqué révoqué). Le second appel avec l'ancien token renvoie HTTP 422 code auth.refresh_token_invalid. | I11: Moyenne | J11: OK | K11: Recette auto (main) — agents | L11: 2026-06-24 | M11: [API] 1er POST /auth/refresh -> 200 avec nouvel accessToken ET nouveau refreshToken (rotation confirmée, ancien != nouveau). Réutilisation de l'ANCIEN refreshToken -> 422 code auth.refresh_token_invalid.
A12: AUTH-10 | B12: Authentification & Sécurité | C12: Déconnexion | D12: Déconnexion révoque le refresh token | E12: Session ouverte avec un refreshToken valide. | F12: refreshToken : <valeur courante> | G12: 1. Appeler POST /api/v1/auth/logout avec le refreshToken. 2. Tenter ensuite POST /api/v1/auth/refresh avec ce même refreshToken. | H12: Le logout renvoie HTTP 204 (No Content) et le token est marqué revokedAt. L'appel refresh suivant renvoie HTTP 422 code auth.refresh_token_invalid. | I12: Moyenne | J12: OK | K12: Recette auto (main) — agents | L12: 2026-06-24 | M12: [API] POST /auth/logout (Bearer access token + body refreshToken) -> 204 ; le refresh suivant avec ce token -> 422 auth.refresh_token_invalid (token révoqué).
A13: AUTH-11 | B13: Authentification & Sécurité | C13: Profil courant | D13: Récupération du profil et des permissions via /me | E13: Utilisateur connecté avec accessToken valide. | F13: Header : Authorization: Bearer <accessToken> | G13: 1. Appeler GET /api/v1/auth/me avec le Bearer token. | H13: Réponse HTTP 200 renvoyant le CurrentUser : userId, tenantId, email, langue préférée, l'ensemble des rôles (dont SUPER_ADMIN si applicable) et la liste des permissions agrégées des rôles. | I13: Moyenne | J13: OK | K13: Recette auto (main) — agents | L13: 2026-06-24 | M13: [API] GET /auth/me -> 200 : CurrentUser avec userId, tenantId, email=admin@recette2.local, preferredLanguage=fr, roles=[TENANT_ADMIN] et 77 permissions agrégées.
... A51: SEC-06 | B51: Isolation multi-tenant & RBAC | C51: Accès inter-tenant par id | D51: Accès à l'organisation d'un autre tenant refusé | E51: Connecté en TENANT_ADMIN du tenant B. Un organizationId appartenant au tenant A est connu. | F51: id = organizationId du tenant A | G51: 1. Avec le token du tenant B, appeler GET /api/v1/organizations/{idDuTenantA}. | H51: Réponse HTTP 403 code auth.forbidden : la règle @PreAuthorize hasRole('SUPER_ADMIN') or @tenantSecurity.isSelf(#id) n'est satisfaite pour aucun des deux critères (ni super-admin, ni son propre tenant). | I51: Haute | J51: OK | K51: Recette auto (main) — agents | L51: 2026-06-24 | M51: [API] Avec le token TENANT_ADMIN du tenant recette2, GET /organizations/{id de l'org du tenant demo} -> 403 code auth.forbidden « Accès refusé » (ni super-admin, ni isSelf).

Sheet 02 - Partenaires
A1: 02 - Partenaires — Partenaires (clients/fournisseurs unifiés), crédits, relevé de compte
A2: ID | B2: Module | C2: Fonctionnalité | D2: Cas de test | E2: Pré-requis | F2: Jeu de données | G2: Étapes | H2: Résultat attendu | I2: Priorité | J2: Statut | K2: Testeur | L2: Date | M2: Observations / Anomalie
A3: PART-01 | B3: Partenaires | C3: Création de partenaire (rôle client) avec code auto | D3: Créer un partenaire client de type Particulier avec code suggéré | E3: Être connecté avec un compte disposant de la permission customer:create. Se trouver sur l'écran Partenaires. | F3: Type = Particulier (INDIVIDUAL) ; Nom = « Ahmed Vall » ; Rôle = Client coché ; Code = laissé tel que suggéré (format P-26-XXXX) ; Plafond client = 0 ; Devise = MRU. | G3: 1. Cliquer sur « Nouveau partenaire ». 2. Vérifier que la case « Client » est cochée par défaut (onglet Tous) et qu'un code est pré-rempli automatiquement. 3. Sélectionner Type = Particulier ; vérifier que le code suggéré devient de la forme P-26-XXXX. 4. Saisir le nom « Ahmed Vall ». 5. Cliquer sur « Enregistrer ». | H3: Le partenaire est créé (HTTP 201). Il apparaît dans la liste avec le code P-26-XXXX, le tag « Client », statut Actif. Les colonnes Dettes et Crédit affichent « — » (solde nul). Le plafond client est enregistré à 0. | I3: Haute | J3: OK | K3: Recette auto (main) — agents | L3: 2026-06-24 | M3: Client Particulier créé HTTP 201 : isCustomer=true, isSupplier=false, customerBalance=0, customerCreditLimit=0, active=true. next-code INDIVIDUAL=P-26-0001 (format P-26-XXXX).
A4: PART-02 | B4: Partenaires | C4: Création de partenaire (rôle fournisseur) de type Société | D4: Créer un partenaire fournisseur de type Société (code préfixe E) | E4: Être connecté avec la permission supplier:create. Écran Partenaires. | F4: Type = Société (COMPANY) ; Nom = « SARL Import Plus » ; Rôle = Fournisseur coché, Client décoché ; Plafond fournisseur = 500000 ; Conditions de paiement = « 30 jours ». | G4: 1. Cliquer sur « Nouveau partenaire ». 2. Décocher « Client » et cocher « Fournisseur ». 3. Sélectionner Type = Société ; vérifier que le code suggéré devient de la forme E-26-XXXX. 4. Saisir Nom, Conditions de paiement et Plafond fournisseur. 5. Cliquer sur « Enregistrer ». | H4: Le partenaire est créé (HTTP 201) avec le code E-26-XXXX et le tag « Fournisseur ». Un compteur de solde fournisseur (AP) est initialisé à 0. Le partenaire apparaît dans l'onglet Fournisseurs. | I4: Haute | J4: OK | K4: Recette auto (main) — agents | L4: 2026-06-24 | M4: Fournisseur Société créé HTTP 201 : isSupplier=true, isCustomer=false, supplierBalance=0, supplierCreditLimit=500000, paymentTerms='30 jours'. next-code COMPANY=E-26-0003 (préfixe E).
A5: PART-03 | B5: Partenaires | C5: Création de partenaire bi-rôle (client + fournisseur) | D5: Créer un partenaire portant à la fois les rôles client et fournisseur | E5: Être connecté avec customer:create et supplier:create. Écran Partenaires. | F5: Nom = « Mohamed Lemine » ; Type = Particulier ; Client coché ET Fournisseur coché ; Plafond client = 100000 ; Plafond fournisseur = 200000. | G5: 1. Cliquer sur « Nouveau partenaire ». 2. Cocher les deux cases « Client » et « Fournisseur ». 3. Vérifier que les deux champs de plafond (client et fournisseur) ainsi que les champs taxId / conditions de paiement apparaissent. 4. Renseigner le nom et les plafonds, puis Enregistrer. | H5: Le partenaire est créé (HTTP 201) avec un code unique unique aux deux rôles. Les deux tags « Client » et « Fournisseur » s'affichent. Un compteur AP fournisseur est initialisé. Les boutons de retrait de rôle (rôle fournisseur barré et rôle client) apparaissent dans la liste d'actions. | I5: Haute | J5: OK | K5: Recette auto (main) — agents | L5: 2026-06-24 | M5: Bi-rôle créé HTTP 201 : isCustomer=true ET isSupplier=true, customerCreditLimit=100000, supplierCreditLimit=200000, code unique.
A6: PART-04 | B6: Partenaires | C6: Validation — aucun rôle sélectionné à la création | D6: Refuser la création d'un partenaire sans aucun rôle | E6: Être connecté avec customer:create ou supplier:create. Écran Partenaires. | F6: Nom = « Test sans rôle » ; cases Client et Fournisseur toutes deux décochées. | G6: 1. Cliquer sur « Nouveau partenaire ». 2. Décocher « Client » et « Fournisseur ». 3. Saisir un nom. 4. Cliquer sur « Enregistrer ». | H6: La création est bloquée. Côté UI, le message rouge « Sélectionnez au moins un rôle (client ou fournisseur). » s'affiche et aucun appel n'est envoyé. Si l'appel atteint le serveur, il renvoie une erreur métier (error.partner.role_required, HTTP 400/422). | I6: Haute | J6: OK | K6: Recette auto (main) — agents | L6: 2026-06-24 | M6: Aucun rôle : rejeté HTTP 422 code=error.partner.role_required. [captures: PART-04-norole.png]
A7: PART-05 | B7: Partenaires | C7: Validation — code obligatoire | D7: Refuser la création d'un partenaire avec code vide | E7: Être connecté avec customer:create. Écran Partenaires. | F7: Nom = « Client sans code » ; Rôle = Client ; Code = vidé manuellement. | G7: 1. Cliquer sur « Nouveau partenaire ». 2. Effacer entièrement le contenu du champ Code. 3. Saisir le nom. 4. Cliquer sur « Enregistrer ». | H7: La création est bloquée. Le champ Code passe en rouge avec le message « requis » et l'enregistrement n'est pas envoyé. Côté API, un code vide est rejeté par la validation @NotBlank (HTTP 400) / la règle error.partner.code_required. | I7: Haute | J7: OK | K7: Recette auto (main) — agents | L7: 2026-06-24 | M7: Code vide : rejeté HTTP 422 validation (champ code/NotBlank). {"timestamp":"2026-06-24T18:34:55.184609882Z","status":422,"error":"Unprocessable Entity","code":"validation.failed","message":"Les données fournies n
A8: PART-06 | B8: Partenaires | C8: Validation — code en double | D8: Refuser la création d'un partenaire avec un code déjà existant | E8: Être connecté avec customer:create. Un partenaire existant possède le code « E-26-0001 ». | F8: Nom = « Doublon » ; Rôle = Client ; Code saisi manuellement = « E-26-0001 » (déjà pris). | G8: 1. Cliquer sur « Nouveau partenaire ». 2. Saisir manuellement le code « E-26-0001 ». 3. Renseigner le nom et cocher Client. 4. Cliquer sur « Enregistrer ». | H8: La création échoue avec un conflit (HTTP 409, code error.data_integrity, champ = code). Un toast d'erreur s'affiche (« Conflit d'intégrité des données »). Le partenaire n'est pas créé. | I8: Haute | J8: OK | K8: Recette auto (main) — agents | L8: 2026-06-24 | M8: Code en double (R2-D02-E02-095025) : rejeté HTTP 409 error.data_integrity. {"timestamp":"2026-06-24T18:34:55.187703424Z","status":409,"error":"Conflict","code":"error.data_integrity","message":"C
A9: PART-07 | B9: Partenaires | C9: Suggestion du prochain code (next-code) | D9: Vérifier l'incrément automatique du code suggéré par type | E9: Être connecté avec customer:create. Le dernier code Société de l'année est « E-26-0007 ». | F9: Type sélectionné = Société puis Particulier. Année courante = 2026 (suffixe 26). | G9: 1. Ouvrir le formulaire de création. 2. Sélectionner Type = Société et observer le code suggéré. 3. Sélectionner Type = Particulier et observer le code suggéré. | H9: Pour Société, le code proposé est « E-26-0008 » (préfixe E, dernier max + 1, sur 4 chiffres). Pour Particulier, le code proposé suit le format « P-26-NNNN » avec sa propre séquence. Le code reste éditable manuellement. | I9: Moyenne | J9: OK | K9: Recette auto (main) — agents | L9: 2026-06-24 | M9: next-code par type : Société E-26-0003→E-26-0004 (max+1, 4 chiffres) après création ; Particulier suit sa propre séquence P-26-0001 (P-26-XXXX). Code éditable.
A10: PART-08 | B10: Partenaires | C10: Édition d'un partenaire | D10: Modifier les coordonnées d'un partenaire existant | E10: Être connecté avec customer:update ou supplier:update. Au moins un partenaire existe. | F10: Nouveau téléphone = « 22 33 44 55 » ; nouvelle adresse = « Nouakchott, Tevragh Zeina » ; nom modifié = « Ahmed Vall Ould Cheikh ». | G10: 1. Dans la liste, cliquer sur l'icône crayon (Modifier) d'un partenaire. 2. Vérifier que le champ Code est grisé / non modifiable. 3. Modifier le nom, le téléphone et l'adresse. 4. Cliquer sur « Enregistrer ». | H10: La modification est enregistrée (HTTP 200). Le code reste inchangé (immuable). Les nouvelles valeurs s'affichent dans la liste après rechargement. Les rôles (client/fournisseur) ne sont pas modifiables via l'édition. | I10: Haute | J10: OK | K10: Recette auto (main) — agents | L10: 2026-06-24 | M10: Édition HTTP 200 : nom/téléphone/adresse persistés ; code immuable (reste R2-D02-P01-095025) ; rôles non modifiables via édition (isSupplier reste false malgré tentative). [captures: PART-08-edit-code-disabled.png]
A11: PART-09 | B11: Partenaires | C11: Désactivation (suppression logique) d'un partenaire | D11: Désactiver un partenaire (soft delete) | E11: Être connecté avec customer:delete ou supplier:delete. Un partenaire actif existe. | F11: Partenaire actif quelconque. | G11: 1. Dans la liste, cliquer sur l'icône corbeille (Désactiver) du partenaire actif. 2. Confirmer dans la boîte de dialogue « Désactiver le partenaire « ... » ? ». | H11: La désactivation aboutit (HTTP 204). Le partenaire passe au statut Inactif (active=false) ; c'est une désactivation logique, l'enregistrement n'est pas supprimé. À noter : l'endpoint DELETE n'effectue aucun contrôle de solde — il bascule simplement le drapeau actif. | I11: Haute | J11: OK | K11: Recette auto (main) — agents | L11: 2026-06-24 | M11: Désactivation logique : DELETE HTTP 204, partenaire active=false (non supprimé, GET 200). [captures: PART-09-deactivate-confirm.png]
A12: PART-10 | B12: Partenaires | C12: Activation du rôle fournisseur | D12: Ajouter le rôle fournisseur à un partenaire client existant | E12: Être connecté avec supplier:create. Un partenaire purement client existe (icône « Activer rôle fournisseur » visible). | F12: Conditions de paiement = « 45 jours » ; Identifiant fiscal = « NIF-12345 » ; Plafond fournisseur = 300000. | G12: 1. Sur la ligne d'un partenaire client uniquement, cliquer sur l'icône mallette « Activer rôle fournisseur ». 2. Renseigner taxId, conditions de paiement et plafond fournisseur dans le dialogue. 3. Cliquer sur « Enregistrer ». | H12: Le rôle fournisseur est activé (HTTP 200). Le partenaire porte désormais les deux tags Client + Fournisseur. Un compteur de solde fournisseur (AP) est créé à 0. Les boutons de retrait de rôle apparaissent. | I12: Haute | J12: OK | K12: Recette auto (main) — agents | L12: 2026-06-24 | M12: Activation rôle fournisseur HTTP 200 : isSupplier=true, taxId='NIF-12345', supplierCreditLimit=300000, supplierBalance=0. Partenaire bi-rôle.
A13: PART-11 | B13: Partenaires | C13: Activation du rôle client | D13: Ajouter le rôle client à un partenaire fournisseur existant | E13: Être connecté avec customer:create. Un partenaire purement fournisseur existe (icône « Activer rôle client » visible). | F13: Plafond client = 150000. | G13: 1. Sur la ligne d'un partenaire fournisseur uniquement, cliquer sur l'icône « Activer rôle client ». 2. Saisir un plafond de crédit client. 3. Cliquer sur « Enregistrer ». | H13: Le rôle client est activé (HTTP 200). Le partenaire porte désormais les deux rôles. Le plafond client est enregistré. Le partenaire devient éligible aux fonctions client (crédits, relevé AR). | I13: Haute | J13: OK | K13: Recette auto (main) — agents | L13: 2026-06-24 | M13: Activation rôle client HTTP 200 : isCustomer=true, customerCreditLimit=150000. Partenaire bi-rôle.
... A29: PART-27 | B29: Partenaires | C29: Contrôle de permission | D29: Vérifier le blocage des actions partenaires sans la permission requise | E29: Disposer de comptes avec des permissions distinctes : un compte SANS customer:create/supplier:create, un SANS credit:grant, un SANS credit:withdraw, un SANS customer:read et supplier:read. | F29: Plusieurs comptes aux permissions ciblées. Un partenaire client existant. | G29: 1. Avec un compte sans customer:create ni supplier:create, tenter POST /api/v1/partners. 2. Avec un compte sans credit:grant, tenter POST .../credits. 3. Avec un compte sans credit:withdraw, tenter .../credits/{cid}/withdraw. 4. Avec un compte sans customer:read ni supplier:read, tenter GET .../statement.pdf et GET .../ar-balance. | H29: Chaque appel non autorisé est rejeté (HTTP 403 Forbidden) par les gardes @PreAuthorize : création de partenaire exige customer:create ou supplier:create ; l'abondement de crédit exige credit:grant ; le retrait exige credit:withdraw ; le relevé exige customer:read ou supplier:read ; ar-balance exige customer:read et ap-balance exige supplier:read. Aucune donnée n'est créée ni exposée. | I29: Haute | J29: OK | K29: Recette auto (main) — agents | L29: 2026-06-24 | M29: Gardes @PreAuthorize OK : STOCK create partner=403, VIEWER grant=403, VIEWER create=403, MANAGER withdraw=403, HR statement=403, HR ar-balance=403 (tous 403) ; DRIVER ar-balance=200 (a customer:read).

Sheet 03 - Catalogue & Tarifs
A1: 03 - Catalogue & Tarifs — Produits, Variantes, Attributs, Unités de mesure, Tarification
A2: ID | B2: Module | C2: Fonctionnalité | D2: Cas de test | E2: Pré-requis | F2: Jeu de données | G2: Étapes | H2: Résultat attendu | I2: Priorité | J2: Statut | K2: Testeur | L2: Date | M2: Observations / Anomalie
A3: PROD-01 | B3: Catalogue produits | C3: Produits — création (nominal) | D3: Créer un produit minimal valide | E3: Être connecté avec la permission product:create. Au moins une unité de mesure existe (UoM par défaut semées à la création du tenant, ex. PCE). | F3: SKU = PROD-TEST-001 ; Nom = Savon liquide ; Unité de base = PCE (Pièce) ; Taxe par défaut laissée vide ; Vendable et Achetable cochés ; Tarification uniforme cochée ; Prix de vente = 100. | G3: 1. Ouvrir l'écran Produits. 2. Cliquer sur « Créer ». 3. Saisir le SKU, le Nom, choisir l'unité de base PCE. 4. Saisir le prix de vente 100. 5. Cliquer sur « Enregistrer ». | H3: Le produit est créé (HTTP 201) et apparaît dans la liste. Le taux de taxe par défaut vaut 0,16 (16 %). Un variant par défaut (defaultVariant=true) est généré automatiquement avec le même SKU. Le prix 100 est enregistré sur le tier par défaut (RETAIL) en unité PCE, taxInclusive=false, devise MRU. | I3: Haute | J3: OK | K3: Recette auto (main) — agents | L3: 2026-06-24 | M3: POST /products HTTP 201; defaultTaxRate=0.16 (attendu 0.16); defaultVariant=true sku=R2-D03-PROD-001-tprn3; prix 100 PUT ok=true
A4: PROD-02 | B4: Catalogue produits | C4: Produits — création (erreur) | D4: Refuser un SKU produit en double | E4: Le produit PROD-TEST-001 existe déjà (cf. PROD-01). | F4: SKU = PROD-TEST-001 (déjà pris) ; Nom = Autre savon ; Unité de base = PCE. | G4: 1. Ouvrir Produits > Créer. 2. Saisir le SKU déjà existant PROD-TEST-001. 3. Renseigner le nom et l'unité de base. 4. Cliquer sur « Enregistrer ». | H4: La création est refusée avec un conflit (HTTP 409, code error.data_integrity, field=sku). Aucun nouveau produit n'est créé. | I4: Haute | J4: OK | K4: Recette auto (main) — agents | L4: 2026-06-24 | M4: re-POST SKU dup HTTP 409 code=error.data_integrity field=sku
A5: PROD-03 | B5: Catalogue produits | C5: Produits — création (erreur) | D5: Refuser un code-barres produit en double | E5: Un produit existant porte le code-barres 6111111111111. | F5: SKU = PROD-TEST-002 (unique) ; Nom = Produit B ; Code-barres = 6111111111111 (déjà utilisé) ; Unité de base = PCE. | G5: 1. Ouvrir Produits > Créer. 2. Saisir un SKU unique et le code-barres déjà existant. 3. Cliquer sur « Enregistrer ». | H5: La création est refusée (HTTP 409, code error.data_integrity, field=barcode). Note : un code-barres vide ou en blanc est accepté (converti en null) et n'est pas soumis au contrôle d'unicité. | I5: Moyenne | J5: OK | K5: Recette auto (main) — agents | L5: 2026-06-24 | M5: 1er barcode HTTP 201; 2e même barcode HTTP 409 code=error.data_integrity field=barcode
A6: PROD-04 | B6: Catalogue produits | C6: Produits — création (erreur) | D6: Refuser un produit dont l'unité de base est inconnue | E6: Permission product:create. | F6: SKU = PROD-TEST-003 ; Nom = Produit C ; baseUomId = identifiant UUID inexistant. | G6: 1. Via l'API POST /api/v1/products, envoyer un baseUomId qui ne correspond à aucune unité. 2. Observer la réponse. | H6: La création échoue (HTTP 404, code entity.uom). Idem si categoryId ou brandId fournis n'existent pas (entity.product_category / entity.brand). | I6: Moyenne | J6: OK | K6: Recette auto (main) — agents | L6: 2026-06-24 | M6: uom: HTTP 404 entity.uom; cat: HTTP 404 entity.product_category; brand: HTTP 404 entity.brand
A7: PROD-05 | B7: Catalogue produits | C7: Produits — édition (nominal) | D7: Modifier le nom, le prix et le suivi d'expiration d'un produit | E7: Le produit PROD-TEST-001 existe. Permission product:update. | F7: Nouveau nom = Savon liquide 1L ; cocher « Suivre l'expiration » ; Durée de vie (jours) = 365 ; Prix de vente = 120. | G7: 1. Ouvrir Produits, cliquer sur l'icône crayon de PROD-TEST-001. 2. Constater que le champ SKU est désactivé (non modifiable en édition). 3. Modifier le nom, cocher Suivre l'expiration, saisir 365 jours, changer le prix à 120. 4. Cliquer sur « Enregistrer ». | H7: Le produit est mis à jour (PATCH 200). Le SKU reste inchangé. trackExpiry=true, shelfLifeDays=365. Le prix du tier par défaut passe à 120 (re-upsert sur tous les variants actifs). | I7: Haute | J7: OK | K7: Recette auto (main) — agents | L7: 2026-06-24 | M7: PATCH HTTP 200 trackExpiry=true shelf=365 sku inchangé=true; prix 120 PUT 200
A8: PROD-06 | B8: Catalogue produits | C8: Produits — désactivation/activation | D8: Désactiver puis réactiver un produit | E8: Le produit PROD-TEST-001 est actif. | F8: Produit = PROD-TEST-001. | G8: 1. Dans la liste, cliquer sur le bouton « Désactiver » (icône interdiction) du produit. 2. Confirmer dans la boîte de dialogue. 3. Cocher « Afficher inactifs » pour le retrouver. 4. Cliquer sur « Activer » et confirmer. | H8: À la désactivation, le produit disparaît de la liste par défaut (active=false) et n'apparaît qu'avec « Afficher inactifs ». À la réactivation, active=true et il réapparaît dans la liste normale. | I8: Moyenne | J8: OK | K8: Recette auto (main) — agents | L8: 2026-06-24 | M8: deactivate HTTP 200; masqué par défaut=true; visible includeInactive=false; react HTTP 200 active=true [VÉRIF] faux_KO : (dé)activation via PATCH /products/{id}{active:false/true} (le test initial utilisait DELETE, non mappé). Désactivé→active=false, masqué de la liste par défaut, visible avec includeInactive=true ; réactivé→active=true et réapparaît. Conforme.
A9: PROD-07 | B9: Catalogue produits | C9: Produits — recherche/filtre | D9: Rechercher un produit par texte et filtrer les inactifs | E9: Plusieurs produits existent, dont au moins un inactif. | F9: Terme de recherche = « savon ». | G9: 1. Ouvrir l'écran Produits. 2. Saisir « savon » dans le champ de recherche. 3. Patienter la recherche temporisée (~300 ms). 4. Cocher « Afficher inactifs ». | H9: La liste se restreint aux produits correspondant au terme (SKU/nom/code-barres). Par défaut, les inactifs sont masqués ; en cochant la case, les produits inactifs apparaissent aussi (includeInactive=true). | I9: Basse | J9: OK | K9: Recette auto (main) — agents | L9: 2026-06-24 | M9: GET /products?search=savon HTTP 200, 20 résultats, tous concordants=false [VÉRIF] faux_KO : la recherche utilise le paramètre ?q= (le test initial utilisait ?search=, ignoré → liste complète). q=Savon → 4 résultats filtrés, tous concordants. Conforme.
A10: PROD-08 | B10: Catalogue produits | C10: Catégories produit (API) | D10: Créer une catégorie racine puis une sous-catégorie | E10: Permission product:create. Endpoint /api/v1/product-categories (pas d'écran dédié — gestion par API). | F10: Catégorie racine : code = HYG, nom = Hygiène. Sous-catégorie : code = HYG-SAV, nom = Savons, parentId = id de HYG. | G10: 1. POST /api/v1/product-categories avec {code:"HYG", name:"Hygiène"}. 2. POST /api/v1/product-categories avec {code:"HYG-SAV", name:"Savons", parentId:<id HYG>}. 3. GET /api/v1/product-categories. | H10: Les deux catégories sont créées (HTTP 201). L'arbre retourné contient la racine et la sous-catégorie reliée par parentId. sortOrder vaut 0 par défaut. | I10: Moyenne | J10: OK | K10: Recette auto (main) — agents | L10: 2026-06-24 | M10: root HTTP 201; sub HTTP 201 parentId=true sortOrder=0; présent dans l'arbre=true
A11: PROD-09 | B11: Catalogue produits | C11: Catégories produit (API, erreurs) | D11: Refuser un code de catégorie en double et un parent inexistant | E11: La catégorie HYG existe (cf. PROD-08). | F11: Cas A : code = HYG (déjà pris). Cas B : code = NEW1, parentId = UUID inexistant. | G11: 1. POST /api/v1/product-categories avec code=HYG. 2. POST /api/v1/product-categories avec code=NEW1 et un parentId inexistant. | H11: Cas A : conflit (HTTP 409, error.data_integrity, field=code). Cas B : non trouvé (HTTP 404, entity.product_category). | I11: Moyenne | J11: OK | K11: Recette auto (main) — agents | L11: 2026-06-24 | M11: dup code HTTP 409 field=code; bad parent HTTP 404 entity=entity.product_category
A12: PROD-10 | B12: Catalogue produits | C12: Marques (API) | D12: Créer une marque et la rattacher implicitement | E12: Permission product:create. Endpoint /api/v1/brands (pas d'écran dédié). | F12: code = DETOL, nom = Dettol, description = Marque d'hygiène, logoUrl = https://exemple.test/dettol.png. | G12: 1. POST /api/v1/brands avec les données. 2. GET /api/v1/brands. 3. GET /api/v1/brands/{id}. | H12: La marque est créée (HTTP 201, active=true) et listée (réponse paginée). La récupération par id renvoie les champs code, nom, description, logoUrl. | I12: Basse | J12: OK | K12: Recette auto (main) — agents | L12: 2026-06-24 | M12: POST /brands HTTP 201 active=true; getById code=R2-D03-DETOL-cc9h6 desc=true logo=true
A13: PROD-11 | B13: Catalogue produits | C13: Marques (API, erreur) | D13: Refuser un code de marque en double | E13: La marque DETOL existe (cf. PROD-10). | F13: code = DETOL (déjà pris), nom = Dettol bis. | G13: 1. POST /api/v1/brands avec code=DETOL. | H13: La création est refusée (HTTP 409, error.data_integrity, field=code). | I13: Basse | J13: OK | K13: Recette auto (main) — agents | L13: 2026-06-24 | M13: re-POST dup brand HTTP 409 code=error.data_integrity field=code
... A57: PRC-12 | B57: Tarification | C57: Résolution de prix (lot/bulk) | D57: Résoudre les prix de plusieurs articles en une requête | E57: Plusieurs variants avec des prix (et au moins un sans prix). Tier ciblé fourni ou omis. | F57: items = [ {variantId:A, uomId:base}, {variantId:B, uomId:base}, {variantId:C-sans-prix, uomId:base} ] ; priceTierId optionnel. | G57: 1. POST /api/v1/pricing/resolve/bulk avec la liste d'items (quantité forcée à 1 par article). 2. Lire la liste retournée. | H57: Les prix des variants A et B sont résolus et retournés ; le variant C sans prix est silencieusement omis de la réponse (les échecs individuels sont ignorés, pas d'erreur globale). La liste d'items vide est refusée (@NotEmpty, HTTP 400). | I57: Basse | J57: OK | K57: Recette auto (main) — agents | L57: 2026-06-24 | M57: bulk 3 items → 2 résolus (C sans prix omis); liste vide HTTP 422 (@NotEmpty→422)

Sheet 04 - Stock & Inventaire
A1: 04 - Stock & Inventaire — Entrepôts, Stock & mouvements, Transferts, Inventaire physique
A2: ID | B2: Module | C2: Fonctionnalité | D2: Cas de test | E2: Pré-requis | F2: Jeu de données | G2: Étapes | H2: Résultat attendu | I2: Priorité | J2: Statut | K2: Testeur | L2: Date | M2: Observations / Anomalie
A3: WH-01 | B3: Entrepôts | C3: CRUD entrepôt | D3: Lister les entrepôts et vérifier l'entrepôt par défaut amorcé | E3: Utilisateur connecté disposant de la permission stock:read. Tenant fraîchement créé (l'entrepôt par défaut MAIN est semé automatiquement à la création de l'organisation). | F3: Aucune saisie. | G3: 1. Ouvrir le menu Entrepôts. 2. Observer la liste affichée. 3. Repérer la colonne « Par défaut » et la colonne « Actif ». | H3: La liste s'affiche, triée par date de création décroissante. Un entrepôt « Main warehouse » (code MAIN) est présent, marqué comme par défaut (icône étoile pleine) et actif. Chaque entrepôt affiche code, nom, type, adresse, statut par défaut et statut actif. | I3: Haute | J3: OK | K3: Recette auto (main) — agents | L3: 2026-06-24 | M3: GET /inventory/warehouses → 200 (3 entrepôts). Exactement 1 entrepôt par défaut: WH-001 "Entrepôt Principal" (active=true). Champs code/nom/type/défaut/actif présents. NB ce tenant: défaut=WH-001 "Entrepôt Principal" (pas de code "MAIN", c'est l'entrepôt amorcé). Preuve: HTTP 200; default=[WH-001]; cols OK.
A4: WH-02 | B4: Entrepôts | C4: CRUD entrepôt | D4: Créer un nouvel entrepôt (cas nominal) | E4: Utilisateur connecté disposant de la permission warehouse:manage. | F4: Code : DEPOT-NORD ; Nom : Dépôt Nord ; Type : Secondaire ; Adresse : Zone industrielle Nord ; Par défaut : non coché. | G4: 1. Sur l'écran Entrepôts, cliquer sur « Créer ». 2. Renseigner le code, le nom, sélectionner le type Secondaire et saisir l'adresse. 3. Laisser « Marquer comme par défaut » décoché. 4. Cliquer sur « Enregistrer ». | H4: L'entrepôt est créé (HTTP 201), le dialogue se ferme et la liste se recharge. Le nouvel entrepôt « Dépôt Nord » apparaît, actif, non par défaut. L'entrepôt MAIN reste l'entrepôt par défaut. | I4: Haute | J4: OK | K4: Recette auto (main) — agents | L4: 2026-06-24 | M4: Entrepôt R2-D04-DEPOT déjà présent (409 doublon d'un run précédent), réutilisé id=8bb565b7-15b3-4d5d-bf23-c73e49a80c79. La création nominale est confirmée par sa présence active/non-défaut.
A5: WH-03 | B5: Entrepôts | C5: CRUD entrepôt - validation | D5: Refus de création avec code ou nom manquant | E5: Utilisateur connecté avec warehouse:manage. Dialogue de création ouvert. | F5: Code : vide ; Nom : vide. | G5: 1. Ouvrir le dialogue « Créer ». 2. Laisser le code et le nom vides. 3. Cliquer sur « Enregistrer ». | H5: Aucun appel n'est envoyé au serveur. Les champs Code et Nom passent en rouge (état ng-invalid) et affichent le message « obligatoire ». Le dialogue reste ouvert. | I5: Moyenne | J5: OK | K5: Recette auto (main) — agents | L5: 2026-06-24 | M5: POST code/name vides → 422 validation.failed (NotBlank code+name). Côté UI ces champs passent en rouge. Preuve: HTTP 422; {"timestamp":"2026-06-24T18:34:56.987862675Z","status":422,"error":"Unprocessable Entity","code":"validation.failed","message":"Les données fournies ne sont pas valides.","path":"/api/v1/inventory/war
A6: WH-04 | B6: Entrepôts | C6: CRUD entrepôt - unicité du code | D6: Refus de création d'un entrepôt avec un code déjà existant | E6: Utilisateur connecté avec warehouse:manage. L'entrepôt par défaut de code MAIN existe. | F6: Code : MAIN ; Nom : Doublon test. | G6: 1. Ouvrir le dialogue « Créer ». 2. Saisir le code MAIN (déjà utilisé) et un nom quelconque. 3. Cliquer sur « Enregistrer ». | H6: Le serveur renvoie une erreur de conflit (HTTP 409, ConflictException error.data_integrity sur le champ code/valeur). L'entrepôt n'est pas créé. La contrainte d'unicité porte sur (tenant, code). | I6: Haute | J6: OK | K6: Recette auto (main) — agents | L6: 2026-06-24 | M6: POST code=WH-001 (doublon de l'entrepôt amorcé) → 409 error.data_integrity. Non créé. Preuve: HTTP 409; {"timestamp":"2026-06-24T18:34:56.990289425Z","status":409,"error":"Conflict","code":"error.data_integrity","message":"Conflit d'intégrité des données","path":"/api/v1/inventory/warehouses","traceId":
A7: WH-05 | B7: Entrepôts | C7: Entrepôt par défaut | D7: Définir un autre entrepôt comme entrepôt par défaut | E7: Utilisateur connecté avec warehouse:manage. Au moins deux entrepôts actifs : MAIN (par défaut) et DEPOT-NORD (non par défaut, actif). | F7: Cible : Dépôt Nord. | G7: 1. Sur la ligne « Dépôt Nord », cliquer sur l'icône étoile « Définir par défaut ». 2. Confirmer dans la boîte de dialogue de confirmation. 3. Observer la liste après rechargement. | H7: POST /api/v1/inventory/warehouses/{id}/set-default réussit. Dépôt Nord devient l'entrepôt par défaut (étoile pleine) et MAIN est rétrogradé (perd son statut par défaut). Il existe toujours exactement un seul entrepôt par défaut. | I7: Haute | J7: OK | K7: Recette auto (main) — agents | L7: 2026-06-24 | M7: POST /set-default sur R2-D04-DEPOT → 200; il devient seul défaut, WH-001 rétrogradé; exactement 1 défaut. WH-001 restauré ensuite (restored=true). Preuve: HTTP 200; defaults=[R2-D04-DEPOT]; exactlyOne=1.
A8: WH-06 | B8: Entrepôts | C8: Entrepôt par défaut - idempotence | D8: Redéfinir comme défaut un entrepôt déjà par défaut (idempotent) | E8: Utilisateur connecté avec warehouse:manage. L'entrepôt par défaut est connu (ex. MAIN). | F8: Cible : l'entrepôt déjà par défaut. | G8: 1. Appeler POST /api/v1/inventory/warehouses/{id}/set-default sur l'entrepôt qui est déjà par défaut (l'UI ne propose pas le bouton pour l'entrepôt déjà par défaut, à exécuter via API). | H8: L'appel réussit sans modification : l'entrepôt reste par défaut, aucun autre entrepôt n'est rétrogradé. Le système conserve toujours exactement un entrepôt par défaut. | I8: Basse | J8: OK | K8: Recette auto (main) — agents | L8: 2026-06-24 | M8: POST /set-default sur WH-001 déjà défaut → 200 idempotent; toujours exactement 1 défaut (WH-001). Preuve: HTTP 200; defaults=[WH-001].
A9: WH-07 | B9: Entrepôts | C9: Activation / désactivation | D9: Désactiver un entrepôt via PATCH (active=false) | E9: Utilisateur connecté avec warehouse:manage. Un entrepôt secondaire actif existe (ex. Dépôt Nord). Remarque : l'écran Entrepôts n'expose ni bouton d'édition ni bascule d'activation ; l'opération passe par l'API. | F9: PATCH /api/v1/inventory/warehouses/{id} avec corps {"active": false}. | G9: 1. Appeler PATCH /api/v1/inventory/warehouses/{id} avec active=false. 2. Recharger la liste des entrepôts. | H9: L'entrepôt passe à inactif (badge « Inactif »). Un entrepôt inactif n'apparaît plus dans la répartition de stock par produit (listStockBreakdownByProduct filtre sur findByActiveTrue) ; il reste cependant utilisable pour des mouvements directs si on cible son identifiant. | I9: Moyenne | J9: OK | K9: Recette auto (main) — agents | L9: 2026-06-24 | M9: PATCH {active:false} → 200; entrepôt listé active=false et exclu de /stocks/by-product. Réactivé ensuite. Preuve: HTTP 200; listedActive=false; byProductExcludes=true.
A10: WH-08 | B10: Entrepôts | C10: Suppression d'un entrepôt | D10: Absence de suppression d'entrepôt (pas d'endpoint DELETE) | E10: Utilisateur connecté avec warehouse:manage. Un entrepôt contenant du stock existe. | F10: Aucune. | G10: 1. Sur l'écran Entrepôts, chercher une action de suppression sur une ligne d'entrepôt. 2. Tenter d'appeler DELETE /api/v1/inventory/warehouses/{id} via l'API. | H10: Aucune action de suppression n'est proposée dans l'UI. Le contrôleur n'expose aucun endpoint DELETE pour les entrepôts : l'appel DELETE renvoie HTTP 405 (méthode non supportée). La mise hors service d'un entrepôt se fait uniquement par désactivation (PATCH active=false). Cela évite la suppression d'un entrepôt non vide. | I10: Moyenne | J10: OK | K10: Recette auto (main) — agents | L10: 2026-06-24 | M10: CORRIGÉ (prior=500): DELETE /inventory/warehouses/{id} → 405 error.method_not_allowed propre. Pas de handler DELETE (Allow: GET,HEAD,PATCH,OPTIONS). Aucune suppression (objet conservé=true). GET single fonctionne aussi (200). Preuve: DELETE → HTTP 405; Allow:GET,HEAD,PATCH,OPTIONS.
A11: STK-01 | B11: Stock | C11: Consultation du stock | D11: Consulter la position de stock (liste globale tous entrepôts) | E11: Utilisateur connecté avec stock:read et reporting:read. Au moins un produit possède du stock. | F11: Filtre entrepôt : « Tous les entrepôts ». | G11: 1. Ouvrir l'écran Stock. 2. Laisser le filtre entrepôt vide (tous les entrepôts). 3. Observer les colonnes affichées. | H11: La page charge les lignes via GET /api/v1/reports/stock. Chaque ligne montre SKU (variante si présente), produit, entrepôt, quantité en main, quantité réservée, quantité disponible, coût moyen, valeur du stock et le statut (OK / Stock faible). Les lignes en stock faible sont remontées en tête (tri is_low_stock DESC). | I11: Haute | J11: OK | K11: Recette auto (main) — agents | L11: 2026-06-24 | M11: GET /reports/stock → 200 (21 lignes); colonnes sku/variantSku/produit/entrepôt/qtyOnHand/qtyReserved/qtyAvailable/averageCost/stockValue/isLowStock présentes. Preuve: HTTP 200; keys OK.
A12: STK-02 | B12: Stock | C12: Consultation par entrepôt | D12: Filtrer la position de stock par entrepôt | E12: Utilisateur connecté avec stock:read/reporting:read. Au moins deux entrepôts ont du stock. | F12: Filtre entrepôt : Dépôt Nord. | G12: 1. Sur l'écran Stock, sélectionner Dépôt Nord dans le filtre « Filtrer par entrepôt ». 2. Observer le rechargement. | H12: Seules les lignes de stock de Dépôt Nord s'affichent (GET /api/v1/reports/stock?warehouseId=...). La colonne entrepôt est masquée (un seul entrepôt sélectionné). | I12: Moyenne | J12: OK | K12: Recette auto (main) — agents | L12: 2026-06-24 | M12: GET /reports/stock?warehouseId=WH-002 → 200; 5 ligne(s), toutes sur WH-002. Preuve: HTTP 200; allSec=true.
A13: STK-03 | B13: Stock | C13: Consultation par produit / par variante | D13: Vérifier la répartition du stock d'un produit par entrepôt et par variante | E13: Utilisateur connecté avec stock:read. Un produit à variantes possède du stock dans plusieurs entrepôts. | F13: Aucune (consultation via GET /api/v1/inventory/stocks/by-product et /api/v1/reports/stock). | G13: 1. Appeler GET /api/v1/inventory/stocks/by-product. 2. Pour un produit donné, examiner les entrées par entrepôt (rollup des variantes vers le produit parent). 3. Sur l'écran Stock, vérifier que chaque ligne distingue la variante (SKU variante + libellé attributs). | H13: by-product renvoie, par produit, une liste d'entrées par entrepôt actif (code, nom, défaut, qtyAvailable = qtyOnHand - qtyReserved), les entrepôts inactifs étant exclus, l'entrepôt par défaut en tête. L'écran Stock affiche une ligne distincte par variante avec son SKU et le libellé d'attributs (ex. « Taille: L · Couleur: Rouge »). | I13: Moyenne | J13: OK | K13: Recette auto (main) — agents | L13: 2026-06-24 | M13: GET /inventory/stocks/by-product → 200; par produit, liste d'entrepôts actifs, entrepôt par défaut en tête (isDefault=true), qtyAvailable exposé. L'écran Stock distingue une ligne par variante (SKU variante). Preuve: HTTP 200; defaultFirst=true; qtyAvailable présent.
... A39: INV-07 | B39: Inventaire | C39: Saisie - lignes partielles | D39: Validation avec lignes partiellement comptées | E39: Utilisateur connecté avec inventory:count. Session avec plusieurs lignes dont certaines non comptées. | F39: Ligne A : compté 18 (théorique 20) ; Ligne B : non saisie. | G39: 1. Saisir uniquement la quantité comptée de la ligne A. 2. Valider la session. | H39: Seule la ligne A (écart -2, countedQty et discrepancy renseignés) génère un ajustement INVENTORY_COUNT. La ligne B, sans countedQty/discrepancy, est ignorée (aucun ajustement, son stock reste inchangé). La session passe à VALIDATED. | I39: Moyenne | J39: OK | K39: Recette auto (main) — agents | L39: 2026-06-24 | M39: Comptage partiel: ligne A saisie (écart -2 → ajustement appliqué -2), ligne B non saisie reste sans countedQty/discrepancy et stock inchangé (0); session VALIDATED. Preuve: HTTP 200; onlyDelta=-2; skippedDelta=0; B non compté.

Sheet 05 - Lots & Expiration
A1: 05 - Lots & Expiration — Lots, FEFO, alertes d'expiration, blocage, destruction, étiquettes
A2: ID | B2: Module | C2: Fonctionnalité | D2: Cas de test | E2: Pré-requis | F2: Jeu de données | G2: Étapes | H2: Résultat attendu | I2: Priorité | J2: Statut | K2: Testeur | L2: Date | M2: Observations / Anomalie
A3: LOT-01 | B3: Lots & Expiration | C3: Création manuelle de lot | D3: Créer un lot manuellement pour une variante avec date d'expiration | E3: Être connecté avec la permission lot:create. Disposer d'une variante (SKU), d'un entrepôt et d'une unité de mesure existants. | F3: variantId valide, warehouseId valide, uomId valide, lotNumber = "LOT-MANU-001", expirationDate = aujourd'hui + 90 jours, productionDate = aujourd'hui, quantity = 50, unitCost = 10 | G3: 1. Envoyer POST /api/v1/lots avec le corps JSON (variantId, warehouseId, uomId, lotNumber, expirationDate, productionDate, quantity, unitCost). 2. Observer le code de réponse HTTP. 3. Lire le corps de la réponse (LotResponse). 4. Recharger l'écran Lots et expiration, onglet "Tous". | H3: HTTP 201 Created. La réponse contient le lot créé : status = "ACTIVE", lotNumber = "LOT-MANU-001", initialQuantity = 50, quantityRemaining = 50, expirationDate renseignée et daysUntilExpiry ≈ 90. Le lot apparaît dans l'onglet "Tous" avec le tag "Actif". | I3: Haute | J3: OK | K3: Recette auto (main) — agents | L3: 2026-06-24 | M3: POST /lots (variante PROD-EXP, R2-D05-MANU-1782326097371, exp J+90, qty 50) → HTTP 201. status=ACTIVE, initialQuantity=50, quantityRemaining=50, daysUntilExpiry=90, expirationDate=2026-09-22.
A4: LOT-02 | B4: Lots & Expiration | C4: Création de lot à la réception | D4: La réception (BRC) d'un produit suivi en expiration crée automatiquement le lot | E4: Produit avec trackExpiry = true. Facture d'achat avec ligne pour ce produit. Réception (BRC) en cours sur cette facture, permissions de réception. | F4: Ligne réceptionnée : quantityReceived = 20, lotNumber = "BRC-LOT-1", expirationDate = aujourd'hui + 180 jours, productionDate = aujourd'hui | G4: 1. Ouvrir l'écran Réception, sélectionner le BRC et passer à l'enregistrement de la réception. 2. Pour la ligne du produit suivi en expiration, saisir la quantité reçue, le n° de lot et la date d'expiration (les champs lot/expiration s'affichent car trackExpiry est vrai). 3. Enregistrer la réception (recordReceipt). 4. Ouvrir l'écran Lots et expiration, onglet "Tous". | H4: La réception est enregistrée (BRC passe à RECEIVED). Un ProductLot ACTIVE est créé pour la variante avec lotNumber = "BRC-LOT-1", initialQuantity = quantityRemaining = 20, l'entrepôt et le coût d'achat de la ligne. Le stock de la variante est augmenté via un mouvement PURCHASE_RECEIPT. Le lot est visible dans l'onglet "Tous". | I4: Haute | J4: OK | K4: Recette auto (main) — agents | L4: 2026-06-24 | M4: Facture achat émise, BRC start+record (lot R2-D05-BRC-1782326097397, exp J+180, qty 20) → HTTP 200, BRC=RECEIVED. Lot créé status=ACTIVE init=20 rem=20. Stock 1340→1360 (+20).
A5: LOT-03 | B5: Lots & Expiration | C5: Création de lot à la réception | D5: Réception d'un produit suivi en expiration sans n° de lot ou sans date refusée | E5: Produit avec trackExpiry = true en cours de réception sur un BRC. | F5: Ligne réceptionnée : quantityReceived = 20, lotNumber laissé vide (ou date d'expiration absente) | G5: 1. Ouvrir l'enregistrement de la réception pour la ligne du produit suivi en expiration. 2. Saisir la quantité reçue mais laisser le n° de lot vide (ou ne pas saisir la date d'expiration). 3. Tenter d'enregistrer la réception. | H5: La réception est refusée côté backend avec l'erreur error.reception.lot_data_required (le n° de lot et la date d'expiration sont obligatoires pour un produit suivi en expiration). Aucun lot n'est créé et le stock n'est pas mouvementé. Côté front, le bouton d'enregistrement reste bloqué tant que lotNumber et expirationDate ne sont pas renseignés. | I5: Haute | J5: OK | K5: Recette auto (main) — agents | L5: 2026-06-24 | M5: Réception produit trackExpiry sans n° de lot ni date → HTTP 422 code=error.reception.lot_data_required. Stock inchangé 1360→1360.
A6: LOT-04 | B6: Lots & Expiration | C6: Réception immédiate | D6: Réception immédiate (complète) interdite pour un produit suivi en expiration | E6: Facture d'achat contenant au moins une ligne d'un produit avec trackExpiry = true. | F6: Facture d'achat avec ligne produit trackExpiry, demande de réception immédiate de la totalité | G6: 1. Déclencher la réception immédiate (receiveImmediately) de la facture d'achat. 2. Observer la réponse. | H6: La réception immédiate est refusée avec l'erreur error.reception.immediate_lot_unsupported : un produit suivi en expiration impose une réception manuelle pour saisir les données de lot. Aucun BRC n'est validé. | I6: Moyenne | J6: OK | K6: Recette auto (main) — agents | L6: 2026-06-24 | M6: POST /goods-receipts/immediate sur facture avec ligne trackExpiry → HTTP 422 "error.reception.immediate_lot_unsupported".
A7: LOT-05 | B7: Lots & Expiration | C7: Stock initial avec lot | D7: Stock initial d'un produit suivi en expiration crée le lot ET le stock | E7: Produit avec trackExpiry = true et une variante. Permission stock:adjust. Écran Stock. | F7: warehouseId valide, variantId valide, quantity = 100, unitCost = 5, lotNumber = "OPEN-001", expirationDate = aujourd'hui + 120 jours, productionDate = aujourd'hui | G7: 1. Ouvrir l'écran Stock et lancer la saisie d'un stock initial pour le produit suivi en expiration. 2. Saisir la quantité et le coût ; comme trackExpiry est vrai, les champs n° de lot et date d'expiration apparaissent et sont obligatoires. 3. Renseigner lotNumber et expirationDate puis valider (POST /api/v1/lots/opening-balance). 4. Vérifier l'écran Lots (onglet Tous) et l'écran Stock. | H7: HTTP 201 Created (réponse = StockMovementDto). Un mouvement de stock OPENING_BALANCE de 100 est posté ET un ProductLot ACTIVE est créé (lotNumber = "OPEN-001", initialQuantity = quantityRemaining = 100). Le lot ligne de stock et le grand-livre du lot restent synchronisés (référence "LOT"). Le lot apparaît dans l'onglet Tous. | I7: Haute | J7: OK | K7: Recette auto (main) — agents | L7: 2026-06-24 | M7: POST /lots/opening-balance (qty 100, R2-D05-OPEN-1782326097435, exp J+120) → HTTP 201, movement type=OPENING_BALANCE referenceType=LOT. Lot ACTIVE init=100 rem=100.
